try:
    print(a)
except Exception as e:
    print(f"Error: {e}")
finally:
    pass